Workbook

Sheet Cover
A1: Did KKR overpay for Spectris?
A2: LBO and valuation case study of KKR's £4.8bn take-private of Spectris plc (completed 4 December 2025)
A4: Question | B4: At £41.75 per share (20.3x 2024 adjusted EBITDA), can KKR earn a typical private equity return?
A5: Answer (base case) | B5: ="About "&TEXT(LBO!C40,"0.0%")&" IRR and "&TEXT(LBO!C39,"0.00")&"x money over 5 years, below a typical ~20% target. Hitting 20% needs a "&TEXT(LBO!C59,"0.0")&"x exit multiple, or ~"&TEXT(LBO!C61-1,"0%")&" more 2030 EBITDA than our plan." -> About 11.5% IRR and 1.72x money over 5 years, below a typical ~20% target. Hitting 20% needs a 24.4x exit multiple, or ~39% more 2030 EBITDA than our plan.
A6: Author | B6: Muhammad Atif Ul Haq
A7: Status | B7: Educational analysis based only on public information. Not investment advice. Projections are the author's assumptions, not KKR's or Spectris's plan.
A9: Sheet guide
A10: Sources | B10: Every hardcoded number and where it came from
A11: Assumptions | B11: All inputs in one place (blue). Change these and everything updates
A12: Historicals | B12: Spectris FY2023-FY2024 reported statements, with tie-out checks
A13: Model | B13: Integrated 3-statement model: income statement, balance sheet, cash flow (FY2025E pro forma at close to FY2030E)
A14: LBO | B14: Sources and uses, returns (IRR, MOIC), value bridge, sensitivities, 'what has to be true'
A15: DCF | B15: Standalone discounted cash flow valuation with WACC build and sensitivity
A16: Comps | B16: Trading multiples of 10 listed peers (UK and US)
A17: Football Field | B17: All valuation methods side by side against the four offers
A19: Colour code
A20: Blue text | B20: Hardcoded input (from a source or an assumption)
A21: Black text | B21: Formula
A22: Green text | B22: Link to another sheet
A23: Yellow fill | B23: Key assumption that drives the answer

Sheet Sources
A1: Sources
A2: Every hardcoded input traces to one of these. Accessed October 2026.
A4: ID | B4: What it supports | C4: Link
A5: S1 | B5: Spectris 2024 full year results (RNS, 28 Feb 2025): income statement, balance sheet, cash flow, adjusted operating profit reconciliation, adjusted D&A | C5: https://www.investegate.co.uk/announcement/rns/spectris--sxs/2024-full-year-results/8756727
A6: S2 | B6: Spectris 2025 half year results (RNS, 7 Aug 2025): H1 revenue, net debt £545.7m, lease liabilities £76.5m, H1 D&A | C6: https://www.spectris.com/assets/HY25-Results_RNS-statement.pdf
A7: S3 | B7: KKR Rule 2.7 announcement (2 Jul 2025): £40.00 offer; FY2024 sales £1,299m, EBITDA £239m, adjusted operating profit £203m; 19.5x / 23.0x | C7: https://www.spectris.com/assets/2.7-Announcement-only.pdf
A8: S4 | B8: Increased KKR offer (5 Aug 2025): £41.75 (£41.47 cash + 28p dividend); equity ~£4.2bn; EV ~£4.8bn; 20.3x EBITDA; 23.9x EBIT; undisturbed £20.38 on 6 Jun 2025 | C8: https://www.spectris.com/assets/Aurora-Increased-Cash-Offer-Announcement-5-August-2025.pdf
A9: S5 | B9: Advent offers: £37.63 (23 Jun 2025, EV ~£4.4bn) and £41.00 (1 Aug 2025, 20.0x / 23.5x) | C9: https://www.spectris.com/assets/Increased-Offer-Announcement-dated-01-August-2025.pdf
A10: S6 | B10: Update on Bidco financing: £1,500m interim term facility; revolving facility increased to £300m (5 Sep 2025) | C10: https://www.spectris.com/assets/Update-on-Bidco-Financing-Arrangement.pdf
A11: S7 | B11: KKR equity syndication update (27 Oct 2025): co-investors up to £926,953,850 = up to 25.39% of Bidco | C11: https://ar.tradingview.com/news/reuters.com%2C2025-10-27%3Anewsml_RSa8405Ea%3A0-reg-kohlberg-kravis-r-spectris-plc-update-on-equity-syndication
A12: S8 | B12: Rule 2.9 announcement (28 Aug 2025): 99,337,919 voting shares in issue | C12: https://www.investegate.co.uk/announcement/rns/spectris--sxs/rule-2-9-announcement/9076538
A13: S9 | B13: Company-compiled consensus (May 2025): FY2025 adjusted operating profit £235.4m (reported by AJ Bell / Alliance News) | C13: https://www.ajbell.co.uk/news/articles/spectris-interim-revenue-and-outlook-affirmed-after-backing-kkr-bid
A14: S10 | B14: Completion of the acquisition on 4 Dec 2025 | C14: https://businesscloud.co.uk/news/kkr-completes-4-7bn-acquisition-of-spectris/
A15: S11 | B15: Peer EV/EBITDA at each peer's fiscal year-end nearest the bid (S&P Global data via stockanalysis.com), e.g. Halma | C15: https://stockanalysis.com/quote/lon/HLMA/financials/ratios/
A16: S12 | B16: Profit Improvement Programme: >£30m savings in 2025, >£50m run-rate by end-2026 (H1 2025 results) | C16: https://www.spectris.com/assets/HY25-Results_RNS-statement.pdf
B18: Derived figures (not directly published) are labelled 'derived' on the sheet where they are used, with the method shown.

Sheet Historicals
A1: Spectris historical financials (as reported)
A2: £m, years ended 31 December. Source S1 unless stated. Checks must show zero.
A4: £m | C4: FY2023 | D4: FY2024
A5: Income statement (statutory)
A6: Revenue | C6: 1449.2 | D6: 1298.7
A7: Cost of sales | C7: -611.1 | D7: -582.8
A8: Gross profit | C8: =C6+C7 -> 838.1 | D8: =D6+D7 -> 715.9
A9: Indirect production and engineering | C9: -126.9 | D9: -112.3
A10: Sales and marketing | C10: -249.6 | D10: -215.7
A11: Administrative expenses | C11: -273 | D11: -290.3
A12: Statutory operating profit | C12: =SUM(C8:C11) -> 188.6 | D12: =SUM(D8:D11) -> 97.6
A13: Check: reported operating profit | C13: 188.6 | D13: 97.6
A14: Check difference (must be 0) | C14: =ROUND(C12-C13,1) -> 0 | D14: =ROUND(D12-D13,1) -> 0
A16: Adjusted operating profit reconciliation
A17: Statutory operating profit | C17: =C12 -> 188.6 | D17: =D12 -> 97.6
A18: Restructuring costs | C18: 0 | D18: 18.3
A19: Transaction-related costs and fair value adjustments | C19: 14 | D19: 16.2
A20: Spectris Foundation contribution | C20: 1 | D20: 0.8
A21: Configuration and customisation costs (SaaS projects) | C21: 40 | D21: 44.7
A22: Amortisation and impairment of acquired intangibles | C22: 18.9 | D22: 25
A23: Adjusted operating profit (adjusted EBIT) | C23: =SUM(C17:C22) -> 262.5 | D23: =SUM(D17:D22) -> 202.6
A24: Adjusted depreciation and software amortisation | C24: 38.8 | D24: 36.1
A25: Adjusted EBITDA | C25: =C23+C24 -> 301.3 | D25: =D23+D24 -> 238.7
A26: Adjusted EBITDA margin | C26: =C25/C6 -> 0.20790781 | D26: =D25/D6 -> 0.18379918
A27: Check: EBITDA quoted in offer documents (S3) | D27: 239
A28: Check difference, rounded (must be 0) | D28: =ROUND(D25-D27,0) -> 0
A30: Balance sheet (31 December)
A31: Goodwill | C31: 565.5 | D31: 1087.5
A32: Other intangible assets | C32: 167.1 | D32: 421.3
A33: Property, plant and equipment | C33: 136.2 | D33: 171.1
A34: Right-of-use assets | C34: 58.1 | D34: 71.3
A35: Other non-current assets | C35: =24.3+21.7+10.8+0.4+5.9+26.6+2.4 -> 92.1 | D35: =23+19.8+10.3+0.9+6.1+22.2+3.8 -> 86.1
A36: Inventories | C36: 231.8 | D36: 250.2
A37: Trade and other receivables | C37: 317.9 | D37: 347
A38: Cash and cash equivalents | C38: 138.5 | D38: 105.7
A39: Other current assets (incl. held for sale) | C39: =7.2+5.8+97.5 -> 110.5 | D39: =17.2+1.9 -> 19.1
A40: Total assets | C40: =SUM(C31:C39) -> 1817.7 | D40: =SUM(D31:D39) -> 2559.3
A41: Trade and other payables | C41: 369.4 | D41: 330.8
A42: Borrowings | C42: 0 | D42: =13.3+641.4 -> 654.7
A43: Lease liabilities | C43: =14.4+48.3 -> 62.7 | D43: =22.1+54.6 -> 76.7
...

Sheet Assumptions
A1: Assumptions
A2: Blue = input. Every input has a source ID (see Sources) or is labelled 'assumption'.
A4: Input | C4: Value | J4: Source / rationale
A5: Deal terms
A6: Offer price per share (£) | C6: 41.75 | J6: S4: final KKR offer, incl. 28p interim dividend
A7: Of which interim dividend paid by Spectris (£) | C7: 0.28 | J7: S4
A8: Fully diluted shares (m) | C8: 101 | J8: Derived: the only share count (100.98m-101.10m) that reproduces all six multiples stated in S3-S5; 99.3m in issue (S8) plus share plans
A9: Spectris net financial debt, 30 Jun 2025 (£m) | C9: 545.7 | J9: S2
A10: Spectris lease liabilities, 30 Jun 2025 (£m) | C10: 76.5 | J10: S2
A11: Undisturbed share price, 6 Jun 2025 (£) | C11: 20.38 | J11: S4
A12: Advent first offer (£) | C12: 37.63 | J12: S5
A13: KKR first offer (£) | C13: 40 | J13: S3
A14: Advent final offer (£) | C14: 41 | J14: S5
A16: Financing
A17: Term loan (£m) | C17: 1500 | J17: S6: interim term facility
A18: Revolving facility, assumed undrawn (£m) | C18: 300 | J18: S6
A19: Interest rate on term loan | C19: 0.065 | J19: Assumption: pricing not public. ~3.5-4% base rates + ~3% margin, blended EUR/USD
A20: Mandatory amortisation (% of original loan p.a.) | C20: 0.01 | J20: Assumption: market standard for a term loan B
A21: Cash sweep (% of excess cash used to repay debt) | C21: 1 | J21: Assumption
A22: Minimum cash balance (£m) | C22: 100 | J22: Assumption: Spectris held £87m at 30 Jun 2025 (S2)
A23: Interest rate on lease liabilities | C23: 0.04 | J23: Assumption
A25: Transaction fees
A26: Stamp duty (% of cash consideration) | C26: 0.005 | J26: UK stamp duty on share transfers (0.5%)
A27: Financing fees (% of term loan) | C27: 0.025 | J27: Assumption: typical arrangement fees
A28: Advisory and other fees (£m) | C28: 60 | J28: Assumption
A30: FY2025E build (deal closes 31 Dec 2025)
A31: H1 2025 revenue (£m) | C31: 636.1 | J31: S2
A32: H1 2024 revenue (£m) | C32: 589.7 | J32: S2
A33: H2 2025 growth vs H2 2024 | C33: 0.04 | J33: Assumption: H1 2025 grew 7.9% reported (1% like-for-like) with acquisitions; order book book-to-bill 1.02x (S2)
A34: FY2025E adjusted operating profit (£m) | C34: 235.4 | J34: S9: company-compiled consensus, May 2025
A36: Operating assumptions by year
D37: FY2025E | E37: FY2026E | F37: FY2027E | G37: FY2028E | H37: FY2029E | I37: FY2030E
A38: Revenue growth | E38: 0.05 | F38: 0.05 | G38: 0.05 | H38: 0.05 | I38: 0.05 | J38: Assumption: mid-single-digit market growth plus pricing
A39: Adjusted EBIT margin | E39: 0.18 | F39: 0.19 | G39: 0.195 | H39: 0.195 | I39: 0.195 | J39: Assumption: >£50m run-rate savings by end-2026 (S12) lift margin above the 18.1% achieved in 2023
A40: D&A incl. right-of-use depreciation (% of revenue) | D40: 0.029 | E40: 0.029 | F40: 0.029 | G40: 0.029 | H40: 0.029 | I40: 0.029 | J40: FY2024 2.8%, H1 2025 3.0% (S1, S2)
A41: Right-of-use depreciation = lease payments (% of revenue) | D41: 0.012 | E41: 0.012 | F41: 0.012 | G41: 0.012 | H41: 0.012 | I41: 0.012 | J41: FY2024 lease principal paid £15.2m = 1.2% of revenue (S1)
A42: Capex (% of revenue) | D42: 0.035 | E42: 0.035 | F42: 0.035 | G42: 0.035 | H42: 0.035 | I42: 0.035 | J42: FY2024 4.0%, H1 2025 3.3% (S1, S2)
A43: Inventories (% of revenue) | D43: =Historicals!$D$58 -> 0.19265419 | E43: =Historicals!$D$58 -> 0.19265419 | F43: =Historicals!$D$58 -> 0.19265419 | G43: =Historicals!$D$58 -> 0.19265419 | H43: =Historicals!$D$58 -> 0.19265419 | I43: =Historicals!$D$58 -> 0.19265419 | J43: Held at FY2024 level
A44: Receivables (% of revenue) | D44: =Historicals!$D$59 -> 0.26719027 | E44: =Historicals!$D$59 -> 0.26719027 | F44: =Historicals!$D$59 -> 0.26719027 | G44: =Historicals!$D$59 -> 0.26719027 | H44: =Historicals!$D$59 -> 0.26719027 | I44: =Historicals!$D$59 -> 0.26719027 | J44: Held at FY2024 level
A45: Payables (% of revenue) | D45: =Historicals!$D$60 -> 0.25471625 | E45: =Historicals!$D$60 -> 0.25471625 | F45: =Historicals!$D$60 -> 0.25471625 | G45: =Historicals!$D$60 -> 0.25471625 | H45: =Historicals!$D$60 -> 0.25471625 | I45: =Historicals!$D$60 -> 0.25471625 | J45: Held at FY2024 level
...

Sheet Model
A1: Integrated 3-statement model
A2: £m. FY2025E column = pro forma balance sheet on completion (31 Dec 2025). Projections FY2026E-FY2030E.
A4: £m | C4: FY2024A | D4: FY2025E | E4: FY2026E | F4: FY2027E | G4: FY2028E | H4: FY2029E | I4: FY2030E
A5: Income statement
A6: Revenue | C6: =Historicals!D6 -> 1298.7 | D6: =Assumptions!$C$31+(Historicals!D6-Assumptions!$C$32)*(1+Assumptions!$C$33) -> 1373.46 | E6: =D6*(1+Assumptions!E$38) -> 1442.133 | F6: =E6*(1+Assumptions!F$38) -> 1514.2396 | G6: =F6*(1+Assumptions!G$38) -> 1589.9516 | H6: =G6*(1+Assumptions!H$38) -> 1669.4492 | I6: =H6*(1+Assumptions!I$38) -> 1752.9217
A7: growth | D7: =D6/C6-1 -> 0.057565258 | E7: =E6/D6-1 -> 0.05 | F7: =F6/E6-1 -> 0.05 | G7: =G6/F6-1 -> 0.05 | H7: =H6/G6-1 -> 0.05 | I7: =I6/H6-1 -> 0.05
A8: Adjusted EBIT | C8: =Historicals!D23 -> 202.6 | D8: =Assumptions!$C$34 -> 235.4 | E8: =E6*Assumptions!E$39 -> 259.58394 | F8: =F6*Assumptions!F$39 -> 287.70553 | G8: =G6*Assumptions!G$39 -> 310.04057 | H8: =H6*Assumptions!H$39 -> 325.5426 | I8: =I6*Assumptions!I$39 -> 341.81973
A9: margin | C9: =C8/C6 -> 0.15600216 | D9: =D8/D6 -> 0.17139196 | E9: =E8/E6 -> 0.18 | F9: =F8/F6 -> 0.19 | G9: =G8/G6 -> 0.195 | H9: =H8/H6 -> 0.195 | I9: =I8/I6 -> 0.195
A10: D&A (incl. right-of-use depreciation) | C10: =Historicals!D24 -> 36.1 | D10: =D6*Assumptions!D$40 -> 39.83034 | E10: =E6*Assumptions!E$40 -> 41.821857 | F10: =F6*Assumptions!F$40 -> 43.91295 | G10: =G6*Assumptions!G$40 -> 46.108597 | H10: =H6*Assumptions!H$40 -> 48.414027 | I10: =I6*Assumptions!I$40 -> 50.834729
A11: of which right-of-use (lease) depreciation | D11: =D6*Assumptions!D$41 -> 16.48152 | E11: =E6*Assumptions!E$41 -> 17.305596 | F11: =F6*Assumptions!F$41 -> 18.170876 | G11: =G6*Assumptions!G$41 -> 19.07942 | H11: =H6*Assumptions!H$41 -> 20.033391 | I11: =I6*Assumptions!I$41 -> 21.03506
A12: Adjusted EBITDA | C12: =C8+C10 -> 238.7 | D12: =D8+D10 -> 275.23034 | E12: =E8+E10 -> 301.4058 | F12: =F8+F10 -> 331.61848 | G12: =G8+G10 -> 356.14917 | H12: =H8+H10 -> 373.95662 | I12: =I8+I10 -> 392.65446
A13: margin | C13: =C12/C6 -> 0.18379918 | D13: =D12/D6 -> 0.20039196 | E13: =E12/E6 -> 0.209 | F13: =F12/F6 -> 0.219 | G13: =G12/G6 -> 0.224 | H13: =H12/H6 -> 0.224 | I13: =I12/I6 -> 0.224
A14: Restructuring costs | E14: =-Assumptions!E$47 -> -20 | F14: =-Assumptions!F$47 -> -10 | G14: =-Assumptions!G$47 -> 0 | H14: =-Assumptions!H$47 -> 0 | I14: =-Assumptions!I$47 -> 0
A15: Interest on term loan | E15: =-D30*Assumptions!$C$19 -> -97.5 | F15: =-E30*Assumptions!$C$19 -> -93.325519 | G15: =-F30*Assumptions!$C$19 -> -87.21925 | H15: =-G30*Assumptions!$C$19 -> -79.375622 | I15: =-H30*Assumptions!$C$19 -> -70.537381
A16: Interest on lease liabilities | E16: =-D31*Assumptions!$C$23 -> -3.06 | F16: =-E31*Assumptions!$C$23 -> -3.06 | G16: =-F31*Assumptions!$C$23 -> -3.06 | H16: =-G31*Assumptions!$C$23 -> -3.06 | I16: =-H31*Assumptions!$C$23 -> -3.06
A17: Profit before tax | E17: =E8+E14+E15+E16 -> 139.02394 | F17: =F8+F14+F15+F16 -> 181.32001 | G17: =G8+G14+G15+G16 -> 219.76132 | H17: =H8+H14+H15+H16 -> 243.10697 | I17: =I8+I14+I15+I16 -> 268.22235
A18: Tax | E18: =-MAX(0,E17)*Assumptions!E$46 -> -34.755985 | F18: =-MAX(0,F17)*Assumptions!F$46 -> -45.330004 | G18: =-MAX(0,G17)*Assumptions!G$46 -> -54.94033 | H18: =-MAX(0,H17)*Assumptions!H$46 -> -60.776744 | I18: =-MAX(0,I17)*Assumptions!I$46 -> -67.055586
A19: Net income | E19: =E17+E18 -> 104.26796 | F19: =F17+F18 -> 135.99001 | G19: =G17+G18 -> 164.82099 | H19: =H17+H18 -> 182.33023 | I19: =I17+I18 -> 201.16676
A21: Balance sheet
A22: Cash | C22: =Historicals!D38 -> 105.7 | D22: =Assumptions!$C$22 -> 100 | E22: =D22+E50 -> 100 | F22: =E22+F50 -> 100 | G22: =F22+G50 -> 100 | H22: =G22+H50 -> 100 | I22: =H22+I50 -> 100
A23: Inventories | C23: =Historicals!D36 -> 250.2 | D23: =D6*Assumptions!D$43 -> 264.60283 | E23: =E6*Assumptions!E$43 -> 277.83297 | F23: =F6*Assumptions!F$43 -> 291.72462 | G23: =G6*Assumptions!G$43 -> 306.31085 | H23: =H6*Assumptions!H$43 -> 321.62639 | I23: =I6*Assumptions!I$43 -> 337.70771
A24: Trade and other receivables | C24: =Historicals!D37 -> 347 | D24: =D6*Assumptions!D$44 -> 366.97514 | E24: =E6*Assumptions!E$44 -> 385.3239 | F24: =F6*Assumptions!F$44 -> 404.5901 | G24: =G6*Assumptions!G$44 -> 424.8196 | H24: =H6*Assumptions!H$44 -> 446.06058 | I24: =I6*Assumptions!I$44 -> 468.36361
A25: PP&E and software | C25: =Historicals!D33 -> 171.1 | D25: =C25+D6*Assumptions!D$42-(D10-D11) -> 195.82228 | E25: =D25-E44-(E10-E11) -> 221.78067 | F25: =E25-F44-(F10-F11) -> 249.03699 | G25: =F25-G44-(G10-G11) -> 277.65612 | H25: =G25-H44-(H10-H11) -> 307.7062 | I25: =H25-I44-(I10-I11) -> 339.25879
A26: Right-of-use assets | C26: =Historicals!D34 -> 71.3 | D26: =C26 -> 71.3 | E26: =D26+E11-E11 -> 71.3 | F26: =E26+F11-F11 -> 71.3 | G26: =F26+G11-G11 -> 71.3 | H26: =G26+H11-H11 -> 71.3 | I26: =H26+I11-I11 -> 71.3 | J26: Leases renewed as they expire: new right-of-use assets = depreciation, so the balance stays flat
A27: Goodwill and acquired intangibles | D27: =D34-SUM(D22:D26) -> 4290.0923 | E27: =D27 -> 4290.0923 | F27: =E27 -> 4290.0923 | G27: =F27 -> 4290.0923 | H27: =G27 -> 4290.0923 | I27: =H27 -> 4290.0923 | J27: Opening goodwill = price paid above the book value of the assets bought (balancing item at close)
A28: Total assets | D28: =SUM(D22:D27) -> 5288.7926 | E28: =SUM(E22:E27) -> 5346.3299 | F28: =SUM(F22:F27) -> 5406.744 | G28: =SUM(G22:G27) -> 5470.1789 | H28: =SUM(H22:H27) -> 5536.7855 | I28: =SUM(I22:I27) -> 5606.7224
A29: Trade and other payables | C29: =Historicals!D41 -> 330.8 | D29: =D6*Assumptions!D$45 -> 349.84259 | E29: =E6*Assumptions!E$45 -> 367.33472 | F29: =F6*Assumptions!F$45 -> 385.70145 | G29: =G6*Assumptions!G$45 -> 404.98653 | H29: =H6*Assumptions!H$45 -> 425.23585 | I29: =I6*Assumptions!I$45 -> 446.49764
A30: Term loan | D30: =Assumptions!$C$17 -> 1500 | E30: =D30+E48+E49 -> 1435.7772 | F30: =E30+F48+F49 -> 1341.8346 | G30: =F30+G48+G49 -> 1221.1634 | H30: =G30+H48+H49 -> 1085.1905 | I30: =H30+I48+I49 -> 932.69886
A31: Lease liabilities | D31: =Assumptions!$C$10 -> 76.5 | E31: =D31+E11-E11 -> 76.5 | F31: =E31+F11-F11 -> 76.5 | G31: =F31+G11-G11 -> 76.5 | H31: =G31+H11-H11 -> 76.5 | I31: =H31+I11-I11 -> 76.5
A32: Shareholders' equity | D32: =LBO!C17-LBO!C11 -> 3362.45 | E32: =D32+E19 -> 3466.718 | F32: =E32+F19 -> 3602.708 | G32: =F32+G19 -> 3767.529 | H32: =G32+H19 -> 3949.8592 | I32: =H32+I19 -> 4151.0259
A34: Total liabilities and equity | D34: =SUM(D29:D32) -> 5288.7926 | E34: =SUM(E29:E32) -> 5346.3299 | F34: =SUM(F29:F32) -> 5406.744 | G34: =SUM(G29:G32) -> 5470.1789 | H34: =SUM(H29:H32) -> 5536.7855 | I34: =SUM(I29:I32) -> 5606.7224
A35: Balance check: assets minus liabilities and equity (must be 0) | D35: =ROUND(D28-D34,3) -> 0 | E35: =ROUND(E28-E34,3) -> 0 | F35: =ROUND(F28-F34,3) -> 0 | G35: =ROUND(G28-G34,3) -> 0 | H35: =ROUND(H28-H34,3) -> 0 | I35: =ROUND(I28-I34,3) -> 0
A37: Cash flow statement
A38: Net income | E38: =E19 -> 104.26796 | F38: =F19 -> 135.99001 | G38: =G19 -> 164.82099 | H38: =H19 -> 182.33023 | I38: =I19 -> 201.16676
A39: Add back: D&A | E39: =E10 -> 41.821857 | F39: =F10 -> 43.91295 | G39: =G10 -> 46.108597 | H39: =H10 -> 48.414027 | I39: =I10 -> 50.834729
A40: Less: increase in working capital | E40: =-((E23+E24-E29)-(D23+D24-D29)) -> -14.086769 | F40: =-((F23+F24-F29)-(E23+E24-E29)) -> -14.791108 | G40: =-((G23+G24-G29)-(F23+F24-F29)) -> -15.530663 | H40: =-((H23+H24-H29)-(G23+G24-G29)) -> -16.307196 | I40: =-((I23+I24-I29)-(H23+H24-H29)) -> -17.122556
A41: Cash flow from operations | E41: =SUM(E38:E40) -> 132.00304 | F41: =SUM(F38:F40) -> 165.11185 | G41: =SUM(G38:G40) -> 195.39892 | H41: =SUM(H38:H40) -> 214.43706 | I41: =SUM(I38:I40) -> 234.87893
A44: Capital expenditure | E44: =-E6*Assumptions!E$42 -> -50.474655 | F44: =-F6*Assumptions!F$42 -> -52.998388 | G44: =-G6*Assumptions!G$42 -> -55.648307 | H44: =-H6*Assumptions!H$42 -> -58.430722 | I44: =-I6*Assumptions!I$42 -> -61.352259
A45: Cash flow from investing | E45: =E44 -> -50.474655 | F45: =F44 -> -52.998388 | G45: =G44 -> -55.648307 | H45: =H44 -> -58.430722 | I45: =I44 -> -61.352259
A46: Lease payments (principal) | E46: =-E11 -> -17.305596 | F46: =-F11 -> -18.170876 | G46: =-G11 -> -19.07942 | H46: =-H11 -> -20.033391 | I46: =-I11 -> -21.03506
...

Sheet LBO
A1: LBO: sources and uses, returns, value bridge
A2: £m unless stated. Entry 31 Dec 2025, exit 31 Dec 2030.
A4: Uses of funds
A5: Purchase of equity (offer price x diluted shares) | C5: =Assumptions!$C$6*Assumptions!$C$8 -> 4216.75
A6: Refinance Spectris net financial debt | C6: =Assumptions!$C$9 -> 545.7
A7: Stamp duty | C7: =Assumptions!$C$26*(Assumptions!$C$6-Assumptions!$C$7)*Assumptions!$C$8 -> 20.94235
A8: Financing fees | C8: =Assumptions!$C$27*Assumptions!$C$17 -> 37.5
A9: Advisory and other fees | C9: =Assumptions!$C$28 -> 60
A11: Total transaction fees | C11: =SUM(C7:C9) -> 118.44235
A12: Cash left on balance sheet | C12: =Assumptions!$C$22 -> 100
A13: Total uses | C13: =C5+C6+C11+C12 -> 4980.8924
A14: Sources of funds
A15: Term loan | C15: =Assumptions!$C$17 -> 1500 | D15: =C15/C18 -> 0.30115086
A16: Revolving facility (undrawn at close) | C16: 0
A17: Sponsor equity (KKR and co-investors) | C17: =C13-C15-C16 -> 3480.8924 | D17: =C17/C18 -> 0.69884914
A18: Total sources | C18: =C15+C16+C17 -> 4980.8924
A19: Check: sources minus uses (must be 0) | C19: =ROUND(C18-C13,3) -> 0
A20: Cross-check: total equity implied by syndication disclosure | C20: =Assumptions!$C$62/Assumptions!$C$63 -> 3650.862 | E20: Derived: co-investors put in up to £927m for up to 25.39% (S7)
A21: Our equity estimate vs disclosure-implied | C21: =C17/C20-1 -> -0.04655602
A23: Entry valuation
A24: Equity value at offer | C24: =C5 -> 4216.75
A25: Plus net financial debt | C25: =C6 -> 545.7
A26: Plus lease liabilities | C26: =Assumptions!$C$10 -> 76.5
A27: Enterprise value (EV) | C27: =SUM(C24:C26) -> 4838.95
A28: EV / FY2024A adjusted EBITDA (offer documents say 20.3x) | C28: =C27/Model!C12 -> 20.272099
A29: EV / FY2024A adjusted EBIT (offer documents say 23.9x) | C29: =C27/Model!C8 -> 23.884255
A30: Entry multiple: EV / FY2025E adjusted EBITDA (LTM at close) | C30: =C27/Model!D12 -> 17.581456
A31: Opening net debt / FY2025E EBITDA (leverage) | C31: =Model!D53/Model!D12 -> 5.0866485
A33: Returns at exit (end FY2030)
A34: FY2030E adjusted EBITDA | C34: =Model!I12 -> 392.65446
A35: Exit multiple | C35: =Assumptions!$C$51 -> 17.581456
A36: Exit enterprise value | C36: =C34*C35 -> 6903.4369
A37: Less: net debt and lease liabilities at exit | C37: =-(Model!I53+Model!I31) -> -909.19886
A38: Exit equity value | C38: =C36+C37 -> 5994.238
A39: Money multiple (MOIC) | C39: =C38/C17 -> 1.7220406
A40: IRR (no interim dividends) | C40: =C39^(1/Assumptions!$C$50)-1 -> 0.11483008
A42: Value bridge: where the equity gain comes from
A43: EBITDA growth (EBITDA increase x entry multiple) | C43: =(Model!I12-Model!D12)*C30 -> 2064.4869 | D43: =C43/SUM($C$43:$C$45) -> 0.78444269 | E43: Share of gross value created ->
A44: Multiple expansion (multiple change x exit EBITDA) | C44: =(C35-C30)*Model!I12 -> 0 | D44: =C44/SUM($C$43:$C$45) -> 0
A45: Debt paydown (fall in net debt) | C45: =Model!D53-Model!I53 -> 567.30114 | D45: =C45/SUM($C$43:$C$45) -> 0.21555731
...

Sheet DCF
A1: Standalone DCF (Spectris as an independent listed company)
A2: £m. Valuation date 31 Dec 2025. Leases treated as an operating cost (rent), then lease liabilities added back so EV is comparable with the offer EV.
A4: Cost of capital (WACC)
A5: Cost of equity = risk-free + beta x equity risk premium | C5: =Assumptions!$C$52+Assumptions!$C$53*Assumptions!$C$54 -> 0.0985
A6: After-tax cost of debt | C6: =Assumptions!$C$55*(1-Assumptions!$E$46) -> 0.0375
A7: WACC | C7: =(1-Assumptions!$C$56)*C5+Assumptions!$C$56*C6 -> 0.08935
A8: Terminal growth | C8: =Assumptions!$C$57 -> 0.025
A10: £m | E10: FY2026E | F10: FY2027E | G10: FY2028E | H10: FY2029E | I10: FY2030E
A11: Adjusted EBIT | E11: =Model!E8 -> 259.58394 | F11: =Model!F8 -> 287.70553 | G11: =Model!G8 -> 310.04057 | H11: =Model!H8 -> 325.5426 | I11: =Model!I8 -> 341.81973
A12: Less: lease interest (rent treated as a cost) | E12: =Model!E16 -> -3.06 | F12: =Model!F16 -> -3.06 | G12: =Model!G16 -> -3.06 | H12: =Model!H16 -> -3.06 | I12: =Model!I16 -> -3.06
A13: Less: restructuring costs | E13: =Model!E14 -> -20 | F13: =Model!F14 -> -10 | G13: =Model!G14 -> 0 | H13: =Model!H14 -> 0 | I13: =Model!I14 -> 0
A14: Less: tax on operating profit | E14: =-(E11+E12+E13)*Assumptions!E$46 -> -59.130985 | F14: =-(F11+F12+F13)*Assumptions!F$46 -> -68.661383 | G14: =-(G11+G12+G13)*Assumptions!G$46 -> -76.745142 | H14: =-(H11+H12+H13)*Assumptions!H$46 -> -80.620649 | I14: =-(I11+I12+I13)*Assumptions!I$46 -> -84.689932
A15: NOPAT | E15: =SUM(E11:E14) -> 177.39296 | F15: =SUM(F11:F14) -> 205.98415 | G15: =SUM(G11:G14) -> 230.23543 | H15: =SUM(H11:H14) -> 241.86195 | I15: =SUM(I11:I14) -> 254.06979
A16: Add: D&A excl. right-of-use (lease) depreciation | E16: =Model!E10-Model!E11 -> 24.516261 | F16: =Model!F10-Model!F11 -> 25.742074 | G16: =Model!G10-Model!G11 -> 27.029178 | H16: =Model!H10-Model!H11 -> 28.380637 | I16: =Model!I10-Model!I11 -> 29.799668
A17: Less: capex | E17: =Model!E44 -> -50.474655 | F17: =Model!F44 -> -52.998388 | G17: =Model!G44 -> -55.648307 | H17: =Model!H44 -> -58.430722 | I17: =Model!I44 -> -61.352259
A18: Less: increase in working capital | E18: =Model!E40 -> -14.086769 | F18: =Model!F40 -> -14.791108 | G18: =Model!G40 -> -15.530663 | H18: =Model!H40 -> -16.307196 | I18: =Model!I40 -> -17.122556
A19: Unlevered free cash flow | E19: =SUM(E15:E18) -> 137.34779 | F19: =SUM(F15:F18) -> 163.93673 | G19: =SUM(G15:G18) -> 186.08563 | H19: =SUM(H15:H18) -> 195.50467 | I19: =SUM(I15:I18) -> 205.39465
A20: Discount period (years) | E20: 1 | F20: 2 | G20: 3 | H20: 4 | I20: 5
A21: Discount factor | E21: =1/(1+$C$7)^E20 -> 0.91797861 | F21: =1/(1+$C$7)^F20 -> 0.84268473 | G21: =1/(1+$C$7)^G20 -> 0.77356656 | H21: =1/(1+$C$7)^H20 -> 0.71011755 | I21: =1/(1+$C$7)^I20 -> 0.65187273
A22: Present value | E22: =E19*E21 -> 126.08234 | F22: =F19*F21 -> 138.14698 | G22: =G19*G21 -> 143.94962 | H22: =H19*H21 -> 138.8313 | I22: =I19*I21 -> 133.89117
A24: Sum of PV of cash flows | C24: =SUM(E22:I22) -> 680.9014
A25: Terminal value (Gordon growth) | C25: =I19*(1+C8)/(C7-C8) -> 3271.6319
A26: PV of terminal value | C26: =C25*I21 -> 2132.6876
A27: Enterprise value (leases as rent) | C27: =C24+C26 -> 2813.589
A28: Add: lease liabilities (comparable with offer EV) | C28: =Assumptions!$C$10 -> 76.5
A29: DCF enterprise value | C29: =C27+C28 -> 2890.089
A30: Terminal value as % of value | C30: =C26/C27 -> 0.75799543
A31: Implied EV / FY2025E EBITDA | C31: =C29/Model!D12 -> 10.500619
A32: Implied value per share (£) | C32: =(C29-Assumptions!$C$9-Assumptions!$C$10)/Assumptions!$C$8 -> 22.454347
A33: Offer EV / DCF EV | C33: =LBO!C27/C29 -> 1.6743256
A35: Sensitivity: DCF enterprise value (£m) by WACC and terminal growth
A36: WACC down, terminal growth across | C36: 0.02 | D36: =Assumptions!$C$57 -> 0.025 | E36: 0.03
B37: =$C$7-0.01 -> 0.07935 | C37: =SUMPRODUCT($E$19:$I$19/(1+$B37)^$E$20:$I$20)+$I$19*(1+C$36)/($B37-C$36)/(1+$B37)^$I$20+$C$28 -> 3186.3821 | D37: =SUMPRODUCT($E$19:$I$19/(1+$B37)^$E$20:$I$20)+$I$19*(1+D$36)/($B37-D$36)/(1+$B37)^$I$20+$C$28 -> 3420.9614 | E37: =SUMPRODUCT($E$19:$I$19/(1+$B37)^$E$20:$I$20)+$I$19*(1+E$36)/($B37-E$36)/(1+$B37)^$I$20+$C$28 -> 3703.0745
B38: =$C$7-0.005 -> 0.08435 | C38: =SUMPRODUCT($E$19:$I$19/(1+$B38)^$E$20:$I$20)+$I$19*(1+C$36)/($B38-C$36)/(1+$B38)^$I$20+$C$28 -> 2938.6216 | D38: =SUMPRODUCT($E$19:$I$19/(1+$B38)^$E$20:$I$20)+$I$19*(1+D$36)/($B38-D$36)/(1+$B38)^$I$20+$C$28 -> 3133.1181 | E38: =SUMPRODUCT($E$19:$I$19/(1+$B38)^$E$20:$I$20)+$I$19*(1+E$36)/($B38-E$36)/(1+$B38)^$I$20+$C$28 -> 3363.4006
B39: =$C$7 -> 0.08935 | C39: =SUMPRODUCT($E$19:$I$19/(1+$B39)^$E$20:$I$20)+$I$19*(1+C$36)/($B39-C$36)/(1+$B39)^$I$20+$C$28 -> 2726.6731 | D39: =SUMPRODUCT($E$19:$I$19/(1+$B39)^$E$20:$I$20)+$I$19*(1+D$36)/($B39-D$36)/(1+$B39)^$I$20+$C$28 -> 2890.089 | E39: =SUMPRODUCT($E$19:$I$19/(1+$B39)^$E$20:$I$20)+$I$19*(1+E$36)/($B39-E$36)/(1+$B39)^$I$20+$C$28 -> 3081.0392
B40: =$C$7+0.005 -> 0.09435 | C40: =SUMPRODUCT($E$19:$I$19/(1+$B40)^$E$20:$I$20)+$I$19*(1+C$36)/($B40-C$36)/(1+$B40)^$I$20+$C$28 -> 2543.31 | D40: =SUMPRODUCT($E$19:$I$19/(1+$B40)^$E$20:$I$20)+$I$19*(1+D$36)/($B40-D$36)/(1+$B40)^$I$20+$C$28 -> 2682.1795 | E40: =SUMPRODUCT($E$19:$I$19/(1+$B40)^$E$20:$I$20)+$I$19*(1+E$36)/($B40-E$36)/(1+$B40)^$I$20+$C$28 -> 2842.6292
B41: =$C$7+0.01 -> 0.09935 | C41: =SUMPRODUCT($E$19:$I$19/(1+$B41)^$E$20:$I$20)+$I$19*(1+C$36)/($B41-C$36)/(1+$B41)^$I$20+$C$28 -> 2383.127 | D41: =SUMPRODUCT($E$19:$I$19/(1+$B41)^$E$20:$I$20)+$I$19*(1+D$36)/($B41-D$36)/(1+$B41)^$I$20+$C$28 -> 2502.3026 | E41: =SUMPRODUCT($E$19:$I$19/(1+$B41)^$E$20:$I$20)+$I$19*(1+E$36)/($B41-E$36)/(1+$B41)^$I$20+$C$28 -> 2638.6629

Sheet Comps
A1: Trading comparables
A2: EV / EBITDA at each peer's fiscal year-end nearest the June 2025 bid (S11). Multiples are currency-neutral.
A4: Company | B4: Ticker | C4: Market | D4: Year end | E4: EV/EBITDA | F4: Why it is a peer
A5: Halma | B5: HLMA | C5: UK | D5: Mar-25 | E5: 20.19 | F5: UK safety, environmental and health technology
A6: Renishaw | B6: RSW | C6: UK | D6: Jun-25 | E6: 13.92 | F6: UK precision metrology, closest UK peer to Spectris Dynamics
A7: Oxford Instruments | B7: OXIG | C7: UK | D7: Mar-25 | E7: 11.62 | F7: UK scientific instruments, closest UK peer to Malvern Panalytical
A8: Spirax Group | B8: SPX | C8: UK | D8: Dec-24 | E8: 15.81 | F8: UK industrial engineering, high-margin niche
A9: Rotork | B9: ROR | C9: UK | D9: Dec-24 | E9: 16.13 | F9: UK flow control instruments
A10: Mettler-Toledo | B10: MTD | C10: US | D10: Dec-24 | E10: 22.95 | F10: Precision instruments and lab analysis
A11: Waters | B11: WAT | C11: US | D11: Dec-24 | E11: 22.56 | F11: Analytical instruments (materials and life science)
A12: Bruker | B12: BRKR | C12: US | D12: Dec-24 | E12: 19.09 | F12: Scientific instruments, closest US peer to Spectris Scientific
A13: AMETEK | B13: AME | C13: US | D13: Dec-24 | E13: 20.01 | F13: Electronic instruments, test and measurement
A14: Keysight | B14: KEYS | C14: US | D14: Oct-24 | E14: 23.58 | F14: Test and measurement, peer to Spectris Dynamics
A16: Summary | B16: 25th pct | C16: Median | D16: 75th pct | E16: Implied EV at median (£m)
A17: UK peers | B17: =QUARTILE(E5:E9,1) -> 13.92 | C17: =MEDIAN(E5:E9) -> 15.81 | D17: =QUARTILE(E5:E9,3) -> 16.13 | E17: =C17*Model!$C$12 -> 3773.847
A18: US peers | B18: =QUARTILE(E10:E14,1) -> 20.01 | C18: =MEDIAN(E10:E14) -> 22.56 | D18: =QUARTILE(E10:E14,3) -> 22.95 | E18: =C18*Model!$C$12 -> 5385.072
A19: All peers | B19: =QUARTILE(E5:E14,1) -> 15.89 | C19: =MEDIAN(E5:E14) -> 19.55 | D19: =QUARTILE(E5:E14,3) -> 21.9675 | E19: =C19*Model!$C$12 -> 4666.585
A21: Spectris undisturbed (6 Jun 2025) | C21: =FootballField!C5/Model!C12 -> 11.229912 | F21: Spectris EV at the undisturbed price / FY2024A adjusted EBITDA
A22: KKR final offer | C22: =LBO!C28 -> 20.272099 | F22: Offer EV / FY2024A adjusted EBITDA
A24: Caveat: peer EBITDA is the data provider's standardised figure, not each company's 'adjusted' EBITDA, and year-ends differ by up to 8 months. Treat as indicative ranges.

Sheet FootballField
A1: Football field: Spectris enterprise value by method (£m)
A2: Low and high ends of each range. Offers converted to EV with the same bridge used in the offer documents.
A4: Method | C4: Low | D4: High | E4: Per share low-high | F4: Basis
A5: Undisturbed market value (6 Jun 2025) | C5: =Assumptions!$C$11*Assumptions!$C$8+(Assumptions!$C$9+Assumptions!$C$10) -> 2680.58 | D5: =Assumptions!$C$11*Assumptions!$C$8+(Assumptions!$C$9+Assumptions!$C$10) -> 2680.58 | E5: =TEXT((C5-(Assumptions!$C$9+Assumptions!$C$10))/Assumptions!$C$8,"£0.00")&" - "&TEXT((D5-(Assumptions!$C$9+Assumptions!$C$10))/Assumptions!$C$8,"£0.00") -> £20.38 - £20.38 | F5: Share price £20.38 before any bid was public
A6: DCF (WACC +/-1%, growth 2-3%) | C6: =MIN(DCF!C37:E41) -> 2383.127 | D6: =MAX(DCF!C37:E41) -> 3703.0745 | E6: =TEXT((C6-(Assumptions!$C$9+Assumptions!$C$10))/Assumptions!$C$8,"£0.00")&" - "&TEXT((D6-(Assumptions!$C$9+Assumptions!$C$10))/Assumptions!$C$8,"£0.00") -> £17.43 - £30.50 | F6: Standalone cash flows under our base case
A7: UK peer multiples (25th-75th pct) | C7: =Comps!B17*Model!C12 -> 3322.704 | D7: =Comps!D17*Model!C12 -> 3850.231 | E7: =TEXT((C7-(Assumptions!$C$9+Assumptions!$C$10))/Assumptions!$C$8,"£0.00")&" - "&TEXT((D7-(Assumptions!$C$9+Assumptions!$C$10))/Assumptions!$C$8,"£0.00") -> £26.74 - £31.96 | F7: x FY2024A adjusted EBITDA
A8: LBO ability to pay (20%-15% IRR) | C8: =LBO!D68 -> 3767.0075 | D8: =LBO!C68 -> 4338.2533 | E8: =TEXT((C8-(Assumptions!$C$9+Assumptions!$C$10))/Assumptions!$C$8,"£0.00")&" - "&TEXT((D8-(Assumptions!$C$9+Assumptions!$C$10))/Assumptions!$C$8,"£0.00") -> £31.14 - £36.79 | F8: Max price a buyer could pay and still earn 15-20%
A9: US peer multiples (25th-75th pct) | C9: =Comps!B18*Model!C12 -> 4776.387 | D9: =Comps!D18*Model!C12 -> 5478.165 | E9: =TEXT((C9-(Assumptions!$C$9+Assumptions!$C$10))/Assumptions!$C$8,"£0.00")&" - "&TEXT((D9-(Assumptions!$C$9+Assumptions!$C$10))/Assumptions!$C$8,"£0.00") -> £41.13 - £48.08 | F9: x FY2024A adjusted EBITDA
A11: Offers (enterprise value) | D11: EV/EBITDA
A12: Advent first offer, £37.63 (23 Jun) | C12: =Assumptions!$C$12*Assumptions!$C$8+(Assumptions!$C$9+Assumptions!$C$10) -> 4422.83 | D12: =C12/Model!$C$12 -> 18.528823
A13: KKR first offer, £40.00 (2 Jul) | C13: =Assumptions!$C$13*Assumptions!$C$8+(Assumptions!$C$9+Assumptions!$C$10) -> 4662.2 | D13: =C13/Model!$C$12 -> 19.53163
A14: Advent final offer, £41.00 (1 Aug) | C14: =Assumptions!$C$14*Assumptions!$C$8+(Assumptions!$C$9+Assumptions!$C$10) -> 4763.2 | D14: =C14/Model!$C$12 -> 19.954755
A15: KKR final offer, £41.75 (5 Aug) - paid | C15: =Assumptions!$C$6*Assumptions!$C$8+(Assumptions!$C$9+Assumptions!$C$10) -> 4838.95 | D15: =C15/Model!$C$12 -> 20.272099
